Workbook

Sheet Corkscrew
A1: YoY ARR Corkscrew & Retention Analysis
A2: Generated: | B2: 2026-06-21
A3: ARR Factor (MRR × N): | B3: 12
A5: Item | B5: 2022-M1 | C5: 2022-M2 | D5: 2022-M3 | E5: 2022-M4 | F5: 2022-M5 | G5: 2022-M6 | H5: 2022-M7 | I5: 2022-M8 | J5: 2022-M9 | K5: 2022-M10 | L5: 2022-M11 | M5: 2022-M12 | N5: 2023-M1 | O5: 2023-M2 | P5: 2023-M3 | Q5: 2023-M4 | R5: 2023-M5 | S5: 2023-M6 | T5: 2023-M7 | U5: 2023-M8 | V5: 2023-M9 | W5: 2023-M10 | X5: 2023-M11 | Y5: 2023-M12 | Z5: 2024-M1 | AA5: 2024-M2 | AB5: 2024-M3 | AC5: 2024-M4 | AD5: 2024-M5 | AE5: 2024-M6 | AF5: 2024-M7 | AG5: 2024-M8 | AH5: 2024-M9 | AI5: 2024-M10 | AJ5: 2024-M11 | AK5: 2024-M12 | AL5: 2025-M1 | AM5: 2025-M2 | AN5: 2025-M3 | AO5: 2025-M4 | AP5: 2025-M5 | AQ5: 2025-M6 | AR5: 2025-M7 | AS5: 2025-M8 | AT5: 2025-M9 | AU5: 2025-M10 | AV5: 2025-M11 | AW5: 2025-M12 | AX5: 2026-M1 | AY5: 2026-M2 | AZ5: 2026-M3 | BA5: 2026-M4 | BB5: 2026-M5
A6: (vs. prior year) | B6: vs 2021-M1 | C6: vs 2021-M2 | D6: vs 2021-M3 | E6: vs 2021-M4 | F6: vs 2021-M5 | G6: vs 2021-M6 | H6: vs 2021-M7 | I6: vs 2021-M8 | J6: vs 2021-M9 | K6: vs 2021-M10 | L6: vs 2021-M11 | M6: vs 2021-M12 | N6: vs 2022-M1 | O6: vs 2022-M2 | P6: vs 2022-M3 | Q6: vs 2022-M4 | R6: vs 2022-M5 | S6: vs 2022-M6 | T6: vs 2022-M7 | U6: vs 2022-M8 | V6: vs 2022-M9 | W6: vs 2022-M10 | X6: vs 2022-M11 | Y6: vs 2022-M12 | Z6: vs 2023-M1 | AA6: vs 2023-M2 | AB6: vs 2023-M3 | AC6: vs 2023-M4 | AD6: vs 2023-M5 | AE6: vs 2023-M6 | AF6: vs 2023-M7 | AG6: vs 2023-M8 | AH6: vs 2023-M9 | AI6: vs 2023-M10 | AJ6: vs 2023-M11 | AK6: vs 2023-M12 | AL6: vs 2024-M1 | AM6: vs 2024-M2 | AN6: vs 2024-M3 | AO6: vs 2024-M4 | AP6: vs 2024-M5 | AQ6: vs 2024-M6 | AR6: vs 2024-M7 | AS6: vs 2024-M8 | AT6: vs 2024-M9 | AU6: vs 2024-M10 | AV6: vs 2024-M11 | AW6: vs 2024-M12 | AX6: vs 2025-M1 | AY6: vs 2025-M2 | AZ6: vs 2025-M3 | BA6: vs 2025-M4 | BB6: vs 2025-M5
A8: Beginning ARR (prior year) | B8: =SUMPRODUCT(('Raw Data with Analysis'!B$12:B$108>0)*'Raw Data with Analysis'!B$12:B$108)*$B$3 -> 1484372.4 | C8: =SUMPRODUCT(('Raw Data with Analysis'!C$12:C$108>0)*'Raw Data with Analysis'!C$12:C$108)*$B$3 -> 1520260 | D8: =SUMPRODUCT(('Raw Data with Analysis'!D$12:D$108>0)*'Raw Data with Analysis'!D$12:D$108)*$B$3 -> 1501670 | E8: =SUMPRODUCT(('Raw Data with Analysis'!E$12:E$108>0)*'Raw Data with Analysis'!E$12:E$108)*$B$3 -> 1518254 | F8: =SUMPRODUCT(('Raw Data with Analysis'!F$12:F$108>0)*'Raw Data with Analysis'!F$12:F$108)*$B$3 -> 1550628.8 | G8: =SUMPRODUCT(('Raw Data with Analysis'!G$12:G$108>0)*'Raw Data with Analysis'!G$12:G$108)*$B$3 -> 1577828.9 | H8: =SUMPRODUCT(('Raw Data with Analysis'!H$12:H$108>0)*'Raw Data with Analysis'!H$12:H$108)*$B$3 -> 1453213 | I8: =SUMPRODUCT(('Raw Data with Analysis'!I$12:I$108>0)*'Raw Data with Analysis'!I$12:I$108)*$B$3 -> 1548582 | ... BB8: =SUMPRODUCT(('Raw Data with Analysis'!BB$12:BB$108>0)*'Raw Data with Analysis'!BB$12:BB$108)*$B$3 -> 3775119.3
A9: + New customer ARR | B9: =SUMPRODUCT(('Raw Data with Analysis'!B$12:B$108=0)*('Raw Data with Analysis'!N$12:N$108>0)*'Raw Data with Analysis'!N$12:N$108)*$B$3 -> 297057.59 | C9: =SUMPRODUCT(('Raw Data with Analysis'!C$12:C$108=0)*('Raw Data with Analysis'!O$12:O$108>0)*'Raw Data with Analysis'!O$12:O$108)*$B$3 -> 310557.59 | D9: =SUMPRODUCT(('Raw Data with Analysis'!D$12:D$108=0)*('Raw Data with Analysis'!P$12:P$108>0)*'Raw Data with Analysis'!P$12:P$108)*$B$3 -> 317557.55 | E9: =SUMPRODUCT(('Raw Data with Analysis'!E$12:E$108=0)*('Raw Data with Analysis'!Q$12:Q$108>0)*'Raw Data with Analysis'!Q$12:Q$108)*$B$3 -> 329579.55 | F9: =SUMPRODUCT(('Raw Data with Analysis'!F$12:F$108=0)*('Raw Data with Analysis'!R$12:R$108>0)*'Raw Data with Analysis'!R$12:R$108)*$B$3 -> 329579.55 | G9: =SUMPRODUCT(('Raw Data with Analysis'!G$12:G$108=0)*('Raw Data with Analysis'!S$12:S$108>0)*'Raw Data with Analysis'!S$12:S$108)*$B$3 -> 327604.31 | H9: =SUMPRODUCT(('Raw Data with Analysis'!H$12:H$108=0)*('Raw Data with Analysis'!T$12:T$108>0)*'Raw Data with Analysis'!T$12:T$108)*$B$3 -> 262904.35 | I9: =SUMPRODUCT(('Raw Data with Analysis'!I$12:I$108=0)*('Raw Data with Analysis'!U$12:U$108>0)*'Raw Data with Analysis'!U$12:U$108)*$B$3 -> 270654.35 | ... BB9: =SUMPRODUCT(('Raw Data with Analysis'!BB$12:BB$108=0)*('Raw Data with Analysis'!BN$12:BN$108>0)*'Raw Data with Analysis'!BN$12:BN$108)*$B$3 -> 0
A10: + Expansion (Upsell) | B10: =SUMPRODUCT(('Raw Data with Analysis'!B$12:B$108>0)*('Raw Data with Analysis'!N$12:N$108>'Raw Data with Analysis'!B$12:B$108)*('Raw Data with Analysis'!N$12:N$108-'Raw Data with Analysis'!B$12:B$108))*$B$3 -> 208070.85 | C10: =SUMPRODUCT(('Raw Data with Analysis'!C$12:C$108>0)*('Raw Data with Analysis'!O$12:O$108>'Raw Data with Analysis'!C$12:C$108)*('Raw Data with Analysis'!O$12:O$108-'Raw Data with Analysis'!C$12:C$108))*$B$3 -> 174066.36 | D10: =SUMPRODUCT(('Raw Data with Analysis'!D$12:D$108>0)*('Raw Data with Analysis'!P$12:P$108>'Raw Data with Analysis'!D$12:D$108)*('Raw Data with Analysis'!P$12:P$108-'Raw Data with Analysis'!D$12:D$108))*$B$3 -> 175866.36 | E10: =SUMPRODUCT(('Raw Data with Analysis'!E$12:E$108>0)*('Raw Data with Analysis'!Q$12:Q$108>'Raw Data with Analysis'!E$12:E$108)*('Raw Data with Analysis'!Q$12:Q$108-'Raw Data with Analysis'!E$12:E$108))*$B$3 -> 169190.88 | F10: =SUMPRODUCT(('Raw Data with Analysis'!F$12:F$108>0)*('Raw Data with Analysis'!R$12:R$108>'Raw Data with Analysis'!F$12:F$108)*('Raw Data with Analysis'!R$12:R$108-'Raw Data with Analysis'!F$12:F$108))*$B$3 -> 140116.2 | G10: =SUMPRODUCT(('Raw Data with Analysis'!G$12:G$108>0)*('Raw Data with Analysis'!S$12:S$108>'Raw Data with Analysis'!G$12:G$108)*('Raw Data with Analysis'!S$12:S$108-'Raw Data with Analysis'!G$12:G$108))*$B$3 -> 139166.11 | H10: =SUMPRODUCT(('Raw Data with Analysis'!H$12:H$108>0)*('Raw Data with Analysis'!T$12:T$108>'Raw Data with Analysis'!H$12:H$108)*('Raw Data with Analysis'!T$12:T$108-'Raw Data with Analysis'!H$12:H$108))*$B$3 -> 125983.53 | I10: =SUMPRODUCT(('Raw Data with Analysis'!I$12:I$108>0)*('Raw Data with Analysis'!U$12:U$108>'Raw Data with Analysis'!I$12:I$108)*('Raw Data with Analysis'!U$12:U$108-'Raw Data with Analysis'!I$12:I$108))*$B$3 -> 125983.53 | ... BB10: =SUMPRODUCT(('Raw Data with Analysis'!BB$12:BB$108>0)*('Raw Data with Analysis'!BN$12:BN$108>'Raw Data with Analysis'!BB$12:BB$108)*('Raw Data with Analysis'!BN$12:BN$108-'Raw Data with Analysis'!BB$12:BB$108))*$B$3 -> 1182036.8
A11: - Contraction (Downsell) | B11: =SUMPRODUCT(('Raw Data with Analysis'!B$12:B$108>0)*('Raw Data with Analysis'!N$12:N$108>0)*('Raw Data with Analysis'!N$12:N$108<'Raw Data with Analysis'!B$12:B$108)*('Raw Data with Analysis'!N$12:N$108-'Raw Data with Analysis'!B$12:B$108))*$B$3 -> -126721.37 | C11: =SUMPRODUCT(('Raw Data with Analysis'!C$12:C$108>0)*('Raw Data with Analysis'!O$12:O$108>0)*('Raw Data with Analysis'!O$12:O$108<'Raw Data with Analysis'!C$12:C$108)*('Raw Data with Analysis'!O$12:O$108-'Raw Data with Analysis'!C$12:C$108))*$B$3 -> -126721.37 | D11: =SUMPRODUCT(('Raw Data with Analysis'!D$12:D$108>0)*('Raw Data with Analysis'!P$12:P$108>0)*('Raw Data with Analysis'!P$12:P$108<'Raw Data with Analysis'!D$12:D$108)*('Raw Data with Analysis'!P$12:P$108-'Raw Data with Analysis'!D$12:D$108))*$B$3 -> -108131.37 | E11: =SUMPRODUCT(('Raw Data with Analysis'!E$12:E$108>0)*('Raw Data with Analysis'!Q$12:Q$108>0)*('Raw Data with Analysis'!Q$12:Q$108<'Raw Data with Analysis'!E$12:E$108)*('Raw Data with Analysis'!Q$12:Q$108-'Raw Data with Analysis'!E$12:E$108))*$B$3 -> -117731.37 | F11: =SUMPRODUCT(('Raw Data with Analysis'!F$12:F$108>0)*('Raw Data with Analysis'!R$12:R$108>0)*('Raw Data with Analysis'!R$12:R$108<'Raw Data with Analysis'!F$12:F$108)*('Raw Data with Analysis'!R$12:R$108-'Raw Data with Analysis'!F$12:F$108))*$B$3 -> -120931.37 | G11: =SUMPRODUCT(('Raw Data with Analysis'!G$12:G$108>0)*('Raw Data with Analysis'!S$12:S$108>0)*('Raw Data with Analysis'!S$12:S$108<'Raw Data with Analysis'!G$12:G$108)*('Raw Data with Analysis'!S$12:S$108-'Raw Data with Analysis'!G$12:G$108))*$B$3 -> -120931.57 | H11: =SUMPRODUCT(('Raw Data with Analysis'!H$12:H$108>0)*('Raw Data with Analysis'!T$12:T$108>0)*('Raw Data with Analysis'!T$12:T$108<'Raw Data with Analysis'!H$12:H$108)*('Raw Data with Analysis'!T$12:T$108-'Raw Data with Analysis'!H$12:H$108))*$B$3 -> -130165.43 | I11: =SUMPRODUCT(('Raw Data with Analysis'!I$12:I$108>0)*('Raw Data with Analysis'!U$12:U$108>0)*('Raw Data with Analysis'!U$12:U$108<'Raw Data with Analysis'!I$12:I$108)*('Raw Data with Analysis'!U$12:U$108-'Raw Data with Analysis'!I$12:I$108))*$B$3 -> -130165.23 | ... BB11: =SUMPRODUCT(('Raw Data with Analysis'!BB$12:BB$108>0)*('Raw Data with Analysis'!BN$12:BN$108>0)*('Raw Data with Analysis'!BN$12:BN$108<'Raw Data with Analysis'!BB$12:BB$108)*('Raw Data with Analysis'!BN$12:BN$108-'Raw Data with Analysis'!BB$12:BB$108))*$B$3 -> -216413.76
A12: - Churn | B12: =SUMPRODUCT(('Raw Data with Analysis'!B$12:B$108>0)*('Raw Data with Analysis'!N$12:N$108=0)*(-'Raw Data with Analysis'!B$12:B$108))*$B$3 -> -220251 | C12: =SUMPRODUCT(('Raw Data with Analysis'!C$12:C$108>0)*('Raw Data with Analysis'!O$12:O$108=0)*(-'Raw Data with Analysis'!C$12:C$108))*$B$3 -> -220251 | D12: =SUMPRODUCT(('Raw Data with Analysis'!D$12:D$108>0)*('Raw Data with Analysis'!P$12:P$108=0)*(-'Raw Data with Analysis'!D$12:D$108))*$B$3 -> -223751 | E12: =SUMPRODUCT(('Raw Data with Analysis'!E$12:E$108>0)*('Raw Data with Analysis'!Q$12:Q$108=0)*(-'Raw Data with Analysis'!E$12:E$108))*$B$3 -> -222335 | F12: =SUMPRODUCT(('Raw Data with Analysis'!F$12:F$108>0)*('Raw Data with Analysis'!R$12:R$108=0)*(-'Raw Data with Analysis'!F$12:F$108))*$B$3 -> -222335 | G12: =SUMPRODUCT(('Raw Data with Analysis'!G$12:G$108>0)*('Raw Data with Analysis'!S$12:S$108=0)*(-'Raw Data with Analysis'!G$12:G$108))*$B$3 -> -222335 | H12: =SUMPRODUCT(('Raw Data with Analysis'!H$12:H$108>0)*('Raw Data with Analysis'!T$12:T$108=0)*(-'Raw Data with Analysis'!H$12:H$108))*$B$3 -> -42685 | I12: =SUMPRODUCT(('Raw Data with Analysis'!I$12:I$108>0)*('Raw Data with Analysis'!U$12:U$108=0)*(-'Raw Data with Analysis'!I$12:I$108))*$B$3 -> -138054.16 | ... BB12: =SUMPRODUCT(('Raw Data with Analysis'!BB$12:BB$108>0)*('Raw Data with Analysis'!BN$12:BN$108=0)*(-'Raw Data with Analysis'!BB$12:BB$108))*$B$3 -> -206503.11
A13: Ending ARR | B13: =B8+B9+B10+B11+B12 -> 1642528.5 | C13: =C8+C9+C10+C11+C12 -> 1657911.6 | D13: =D8+D9+D10+D11+D12 -> 1663211.5 | E13: =E8+E9+E10+E11+E12 -> 1676958.1 | F13: =F8+F9+F10+F11+F12 -> 1677058.2 | G13: =G8+G9+G10+G11+G12 -> 1701332.7 | H13: =H8+H9+H10+H11+H12 -> 1669250.5 | I13: =I8+I9+I10+I11+I12 -> 1677000.5 | ... BB13: =BB8+BB9+BB10+BB11+BB12 -> 4534239.2
A14: External Check (Ending - Raw Data) = 0 | B14: =B13 - SUM('Raw Data with Analysis'!N$12:N$108)*$B$3 -> 0 | C14: =C13 - SUM('Raw Data with Analysis'!O$12:O$108)*$B$3 -> 0 | D14: =D13 - SUM('Raw Data with Analysis'!P$12:P$108)*$B$3 -> 0 | E14: =E13 - SUM('Raw Data with Analysis'!Q$12:Q$108)*$B$3 -> 0 | F14: =F13 - SUM('Raw Data with Analysis'!R$12:R$108)*$B$3 -> 0 | G14: =G13 - SUM('Raw Data with Analysis'!S$12:S$108)*$B$3 -> 0 | H14: =H13 - SUM('Raw Data with Analysis'!T$12:T$108)*$B$3 -> 0 | I14: =I13 - SUM('Raw Data with Analysis'!U$12:U$108)*$B$3 -> 0 | ... BB14: =BB13 - SUM('Raw Data with Analysis'!BN$12:BN$108)*$B$3 -> 0
A16: CUSTOMER COUNTS
A17: # Active (prior period) | B17: =HLOOKUP(SUBSTITUTE(B$6,"vs ",""),'Raw Data with Analysis'!$B$1:$BN$2,2,FALSE()) -> 37 | C17: =HLOOKUP(SUBSTITUTE(C$6,"vs ",""),'Raw Data with Analysis'!$B$1:$BN$2,2,FALSE()) -> 37 | D17: =HLOOKUP(SUBSTITUTE(D$6,"vs ",""),'Raw Data with Analysis'!$B$1:$BN$2,2,FALSE()) -> 37 | E17: =HLOOKUP(SUBSTITUTE(E$6,"vs ",""),'Raw Data with Analysis'!$B$1:$BN$2,2,FALSE()) -> 37 | F17: =HLOOKUP(SUBSTITUTE(F$6,"vs ",""),'Raw Data with Analysis'!$B$1:$BN$2,2,FALSE()) -> 37 | G17: =HLOOKUP(SUBSTITUTE(G$6,"vs ",""),'Raw Data with Analysis'!$B$1:$BN$2,2,FALSE()) -> 39 | H17: =HLOOKUP(SUBSTITUTE(H$6,"vs ",""),'Raw Data with Analysis'!$B$1:$BN$2,2,FALSE()) -> 39 | I17: =HLOOKUP(SUBSTITUTE(I$6,"vs ",""),'Raw Data with Analysis'!$B$1:$BN$2,2,FALSE()) -> 41 | ... BB17: =HLOOKUP(SUBSTITUTE(BB$6,"vs ",""),'Raw Data with Analysis'!$B$1:$BN$2,2,FALSE()) -> 66
A18: # Active (current period) | B18: =HLOOKUP(B$5,'Raw Data with Analysis'!$B$1:$BN$2,2,FALSE()) -> 44 | C18: =HLOOKUP(C$5,'Raw Data with Analysis'!$B$1:$BN$2,2,FALSE()) -> 45 | D18: =HLOOKUP(D$5,'Raw Data with Analysis'!$B$1:$BN$2,2,FALSE()) -> 45 | E18: =HLOOKUP(E$5,'Raw Data with Analysis'!$B$1:$BN$2,2,FALSE()) -> 45 | F18: =HLOOKUP(F$5,'Raw Data with Analysis'!$B$1:$BN$2,2,FALSE()) -> 45 | G18: =HLOOKUP(G$5,'Raw Data with Analysis'!$B$1:$BN$2,2,FALSE()) -> 43 | H18: =HLOOKUP(H$5,'Raw Data with Analysis'!$B$1:$BN$2,2,FALSE()) -> 42 | I18: =HLOOKUP(I$5,'Raw Data with Analysis'!$B$1:$BN$2,2,FALSE()) -> 44 | ... BB18: =HLOOKUP(BB$5,'Raw Data with Analysis'!$B$1:$BN$2,2,FALSE()) -> 58
A19: # Churned | B19: =B17 - HLOOKUP(B$5,'Raw Data with Analysis'!$B$1:$BN$3,3,FALSE()) -> 6 | C19: =C17 - HLOOKUP(C$5,'Raw Data with Analysis'!$B$1:$BN$3,3,FALSE()) -> 6 | D19: =D17 - HLOOKUP(D$5,'Raw Data with Analysis'!$B$1:$BN$3,3,FALSE()) -> 7 | E19: =E17 - HLOOKUP(E$5,'Raw Data with Analysis'!$B$1:$BN$3,3,FALSE()) -> 7 | F19: =F17 - HLOOKUP(F$5,'Raw Data with Analysis'!$B$1:$BN$3,3,FALSE()) -> 7 | G19: =G17 - HLOOKUP(G$5,'Raw Data with Analysis'!$B$1:$BN$3,3,FALSE()) -> 7 | H19: =H17 - HLOOKUP(H$5,'Raw Data with Analysis'!$B$1:$BN$3,3,FALSE()) -> 6 | I19: =I17 - HLOOKUP(I$5,'Raw Data with Analysis'!$B$1:$BN$3,3,FALSE()) -> 8 | ... BB19: =BB17 - HLOOKUP(BB$5,'Raw Data with Analysis'!$B$1:$BN$3,3,FALSE()) -> 8
A20: # New | B20: =B18 - HLOOKUP(B$5,'Raw Data with Analysis'!$B$1:$BN$3,3,FALSE()) -> 13 | C20: =C18 - HLOOKUP(C$5,'Raw Data with Analysis'!$B$1:$BN$3,3,FALSE()) -> 14 | D20: =D18 - HLOOKUP(D$5,'Raw Data with Analysis'!$B$1:$BN$3,3,FALSE()) -> 15 | E20: =E18 - HLOOKUP(E$5,'Raw Data with Analysis'!$B$1:$BN$3,3,FALSE()) -> 15 | F20: =F18 - HLOOKUP(F$5,'Raw Data with Analysis'!$B$1:$BN$3,3,FALSE()) -> 15 | G20: =G18 - HLOOKUP(G$5,'Raw Data with Analysis'!$B$1:$BN$3,3,FALSE()) -> 11 | H20: =H18 - HLOOKUP(H$5,'Raw Data with Analysis'!$B$1:$BN$3,3,FALSE()) -> 9 | I20: =I18 - HLOOKUP(I$5,'Raw Data with Analysis'!$B$1:$BN$3,3,FALSE()) -> 11 | ... BB20: =BB18 - HLOOKUP(BB$5,'Raw Data with Analysis'!$B$1:$BN$3,3,FALSE()) -> 0
A22: RETENTION RATES
A23: Gross Dollar Retention (GRR) | B23: =IFERROR((B8+B11+B12)/B8,0) -> 0.76624978 | C23: =IFERROR((C8+C11+C12)/C8,0) -> 0.77176774 | D23: =IFERROR((D8+D11+D12)/D8,0) -> 0.77899114 | E23: =IFERROR((E8+E11+E12)/E8,0) -> 0.77601484 | F23: =IFERROR((F8+F11+F12)/F8,0) -> 0.77862763 | G23: =IFERROR((G8+G11+G12)/G8,0) -> 0.78244373 | H23: =IFERROR((H8+H11+H12)/H8,0) -> 0.88105637 | I23: =IFERROR((I8+I11+I12)/I8,0) -> 0.82679678 | ... BB23: =IFERROR((BB8+BB11+BB12)/BB8,0) -> 0.88797258
A24: Net Dollar Retention (NRR) | B24: =IFERROR((B8+B10+B11+B12)/B8,0) -> 0.90642408 | C24: =IFERROR((C8+C10+C11+C12)/C8,0) -> 0.8862655 | D24: =IFERROR((D8+D10+D11+D12)/D8,0) -> 0.896105 | E24: =IFERROR((E8+E10+E11+E12)/E8,0) -> 0.88745263 | F24: =IFERROR((F8+F10+F11+F12)/F8,0) -> 0.86898852 | G24: =IFERROR((G8+G10+G11+G12)/G8,0) -> 0.87064474 | H24: =IFERROR((H8+H10+H11+H12)/H8,0) -> 0.96774946 | I24: =IFERROR((I8+I10+I11+I12)/I8,0) -> 0.9081509 | ... BB24: =IFERROR((BB8+BB10+BB11+BB12)/BB8,0) -> 1.201085
A25: Logo Retention | B25: =IFERROR((B17-B19)/B17,0) -> 0.83783784 | C25: =IFERROR((C17-C19)/C17,0) -> 0.83783784 | D25: =IFERROR((D17-D19)/D17,0) -> 0.81081081 | E25: =IFERROR((E17-E19)/E17,0) -> 0.81081081 | F25: =IFERROR((F17-F19)/F17,0) -> 0.81081081 | G25: =IFERROR((G17-G19)/G17,0) -> 0.82051282 | H25: =IFERROR((H17-H19)/H17,0) -> 0.84615385 | I25: =IFERROR((I17-I19)/I17,0) -> 0.80487805 | ... BB25: =IFERROR((BB17-BB19)/BB17,0) -> 0.87878788
A27: PER-CUSTOMER METRICS
A28: Avg ARR per Active Customer | B28: =IFERROR(B13/B18,0) -> 37330.192 | C28: =IFERROR(C13/C18,0) -> 36842.48 | D28: =IFERROR(D13/D18,0) -> 36960.257 | E28: =IFERROR(E13/E18,0) -> 37265.735 | F28: =IFERROR(F13/F18,0) -> 37267.96 | G28: =IFERROR(G13/G18,0) -> 39565.878 | H28: =IFERROR(H13/H18,0) -> 39744.059 | I28: =IFERROR(I13/I18,0) -> 38113.647 | ... BB28: =IFERROR(BB13/BB18,0) -> 78176.538
A29: Avg ARR per New Customer | B29: =IFERROR(B9/B20,0) -> 22850.584 | C29: =IFERROR(C9/C20,0) -> 22182.685 | D29: =IFERROR(D9/D20,0) -> 21170.503 | E29: =IFERROR(E9/E20,0) -> 21971.97 | F29: =IFERROR(F9/F20,0) -> 21971.97 | G29: =IFERROR(G9/G20,0) -> 29782.21 | H29: =IFERROR(H9/H20,0) -> 29211.594 | I29: =IFERROR(I9/I20,0) -> 24604.941 | ... BB29: =IFERROR(BB9/BB20,0) -> 0

Sheet Raw Data with Analysis
A1: Customer ID | B1: 2021-M1 | C1: 2021-M2 | D1: 2021-M3 | E1: 2021-M4 | F1: 2021-M5 | G1: 2021-M6 | H1: 2021-M7 | I1: 2021-M8 | J1: 2021-M9 | K1: 2021-M10 | L1: 2021-M11 | M1: 2021-M12 | N1: 2022-M1 | O1: 2022-M2 | P1: 2022-M3 | Q1: 2022-M4 | R1: 2022-M5 | S1: 2022-M6 | T1: 2022-M7 | U1: 2022-M8 | V1: 2022-M9 | W1: 2022-M10 | X1: 2022-M11 | Y1: 2022-M12 | Z1: 2023-M1 | AA1: 2023-M2 | AB1: 2023-M3 | AC1: 2023-M4 | AD1: 2023-M5 | AE1: 2023-M6 | AF1: 2023-M7 | AG1: 2023-M8 | AH1: 2023-M9 | AI1: 2023-M10 | AJ1: 2023-M11 | AK1: 2023-M12 | AL1: 2024-M1 | AM1: 2024-M2 | AN1: 2024-M3 | AO1: 2024-M4 | AP1: 2024-M5 | AQ1: 2024-M6 | AR1: 2024-M7 | AS1: 2024-M8 | AT1: 2024-M9 | AU1: 2024-M10 | AV1: 2024-M11 | AW1: 2024-M12 | AX1: 2025-M1 | AY1: 2025-M2 | AZ1: 2025-M3 | BA1: 2025-M4 | BB1: 2025-M5 | BC1: 2025-M6 | BD1: 2025-M7 | BE1: 2025-M8 | BF1: 2025-M9 | BG1: 2025-M10 | BH1: 2025-M11 | BI1: 2025-M12 | BJ1: 2026-M1 | BK1: 2026-M2 | BL1: 2026-M3 | BM1: 2026-M4 | BN1: 2026-M5 | BO1: Excluded?
A2: # Active customers | B2: =COUNTIF(B$12:B$108,">0") -> 37 | C2: =COUNTIF(C$12:C$108,">0") -> 37 | D2: =COUNTIF(D$12:D$108,">0") -> 37 | E2: =COUNTIF(E$12:E$108,">0") -> 37 | F2: =COUNTIF(F$12:F$108,">0") -> 37 | G2: =COUNTIF(G$12:G$108,">0") -> 39 | H2: =COUNTIF(H$12:H$108,">0") -> 39 | I2: =COUNTIF(I$12:I$108,">0") -> 41 | ... BN2: =COUNTIF(BN$12:BN$108,">0") -> 58
A3: # Retained vs 12mo prior | B3: n/a | C3: n/a | D3: n/a | E3: n/a | F3: n/a | G3: n/a | H3: n/a | I3: n/a | J3: n/a | K3: n/a | L3: n/a | M3: n/a | N3: =SUMPRODUCT((N$12:N$108>0)*(B$12:B$108>0)) -> 31 | O3: =SUMPRODUCT((O$12:O$108>0)*(C$12:C$108>0)) -> 31 | P3: =SUMPRODUCT((P$12:P$108>0)*(D$12:D$108>0)) -> 30 | Q3: =SUMPRODUCT((Q$12:Q$108>0)*(E$12:E$108>0)) -> 30 | R3: =SUMPRODUCT((R$12:R$108>0)*(F$12:F$108>0)) -> 30 | S3: =SUMPRODUCT((S$12:S$108>0)*(G$12:G$108>0)) -> 32 | T3: =SUMPRODUCT((T$12:T$108>0)*(H$12:H$108>0)) -> 33 | U3: =SUMPRODUCT((U$12:U$108>0)*(I$12:I$108>0)) -> 33 | ... BN3: =SUMPRODUCT((BN$12:BN$108>0)*(BB$12:BB$108>0)) -> 58
A12: ='Raw Data'!A12 -> Local Account #1 from CA | B12: =IF('Raw Data'!G12="",0,'Raw Data'!G12) -> 0 | C12: =IF('Raw Data'!H12="",0,'Raw Data'!H12) -> 0 | D12: =IF('Raw Data'!I12="",0,'Raw Data'!I12) -> 0 | E12: =IF('Raw Data'!J12="",0,'Raw Data'!J12) -> 0 | F12: =IF('Raw Data'!K12="",0,'Raw Data'!K12) -> 0 | G12: =IF('Raw Data'!L12="",0,'Raw Data'!L12) -> 0 | H12: =IF('Raw Data'!M12="",0,'Raw Data'!M12) -> 0 | I12: =IF('Raw Data'!N12="",0,'Raw Data'!N12) -> 0 | ... BN12: =IF('Raw Data'!BS12="",0,'Raw Data'!BS12) -> 8236.25 | BO12: =FALSE() -> FALSE
A13: ='Raw Data'!A21 -> Local Account #10 from MI | B13: =IF('Raw Data'!G21="",0,'Raw Data'!G21) -> 0 | C13: =IF('Raw Data'!H21="",0,'Raw Data'!H21) -> 0 | D13: =IF('Raw Data'!I21="",0,'Raw Data'!I21) -> 0 | E13: =IF('Raw Data'!J21="",0,'Raw Data'!J21) -> 682 | F13: =IF('Raw Data'!K21="",0,'Raw Data'!K21) -> 682 | G13: =IF('Raw Data'!L21="",0,'Raw Data'!L21) -> 682 | H13: =IF('Raw Data'!M21="",0,'Raw Data'!M21) -> 682 | I13: =IF('Raw Data'!N21="",0,'Raw Data'!N21) -> 8362.75 | ... BN13: =IF('Raw Data'!BS21="",0,'Raw Data'!BS21) -> 0 | BO13: =FALSE() -> FALSE
A14: ='Raw Data'!A22 -> Local Account #11 from MN | B14: =IF('Raw Data'!G22="",0,'Raw Data'!G22) -> 0 | C14: =IF('Raw Data'!H22="",0,'Raw Data'!H22) -> 0 | D14: =IF('Raw Data'!I22="",0,'Raw Data'!I22) -> 0 | E14: =IF('Raw Data'!J22="",0,'Raw Data'!J22) -> 0 | F14: =IF('Raw Data'!K22="",0,'Raw Data'!K22) -> 0 | G14: =IF('Raw Data'!L22="",0,'Raw Data'!L22) -> 0 | H14: =IF('Raw Data'!M22="",0,'Raw Data'!M22) -> 0 | I14: =IF('Raw Data'!N22="",0,'Raw Data'!N22) -> 0 | ... BN14: =IF('Raw Data'!BS22="",0,'Raw Data'!BS22) -> 3750 | BO14: =FALSE() -> FALSE
A15: ='Raw Data'!A24 -> Local Account #13 from FL | B15: =IF('Raw Data'!G24="",0,'Raw Data'!G24) -> 333.33333 | C15: =IF('Raw Data'!H24="",0,'Raw Data'!H24) -> 333.33333 | D15: =IF('Raw Data'!I24="",0,'Raw Data'!I24) -> 333.33333 | E15: =IF('Raw Data'!J24="",0,'Raw Data'!J24) -> 333.33333 | F15: =IF('Raw Data'!K24="",0,'Raw Data'!K24) -> 333.33333 | G15: =IF('Raw Data'!L24="",0,'Raw Data'!L24) -> 333.33333 | H15: =IF('Raw Data'!M24="",0,'Raw Data'!M24) -> 333.33333 | I15: =IF('Raw Data'!N24="",0,'Raw Data'!N24) -> 333.33333 | ... BN15: =IF('Raw Data'!BS24="",0,'Raw Data'!BS24) -> 437.5 | BO15: =FALSE() -> FALSE
A16: ='Raw Data'!A13 -> Local Account #2 from CA | B16: =IF('Raw Data'!G13="",0,'Raw Data'!G13) -> 0 | C16: =IF('Raw Data'!H13="",0,'Raw Data'!H13) -> 0 | D16: =IF('Raw Data'!I13="",0,'Raw Data'!I13) -> 0 | E16: =IF('Raw Data'!J13="",0,'Raw Data'!J13) -> 0 | F16: =IF('Raw Data'!K13="",0,'Raw Data'!K13) -> 0 | G16: =IF('Raw Data'!L13="",0,'Raw Data'!L13) -> 0 | H16: =IF('Raw Data'!M13="",0,'Raw Data'!M13) -> 0 | I16: =IF('Raw Data'!N13="",0,'Raw Data'!N13) -> 0 | ... BN16: =IF('Raw Data'!BS13="",0,'Raw Data'!BS13) -> 0 | BO16: =FALSE() -> FALSE
A17: ='Raw Data'!A32 -> Local Account #22 from FL | B17: =IF('Raw Data'!G32="",0,'Raw Data'!G32) -> 3750 | C17: =IF('Raw Data'!H32="",0,'Raw Data'!H32) -> 3750 | D17: =IF('Raw Data'!I32="",0,'Raw Data'!I32) -> 3750 | E17: =IF('Raw Data'!J32="",0,'Raw Data'!J32) -> 3750 | F17: =IF('Raw Data'!K32="",0,'Raw Data'!K32) -> 3750 | G17: =IF('Raw Data'!L32="",0,'Raw Data'!L32) -> 3750 | H17: =IF('Raw Data'!M32="",0,'Raw Data'!M32) -> 3750 | I17: =IF('Raw Data'!N32="",0,'Raw Data'!N32) -> 3750 | ... BN17: =IF('Raw Data'!BS32="",0,'Raw Data'!BS32) -> 0 | BO17: =FALSE() -> FALSE
A18: ='Raw Data'!A33 -> Local Account #23 from WA | B18: =IF('Raw Data'!G33="",0,'Raw Data'!G33) -> 516.66667 | C18: =IF('Raw Data'!H33="",0,'Raw Data'!H33) -> 516.66667 | D18: =IF('Raw Data'!I33="",0,'Raw Data'!I33) -> 516.66667 | E18: =IF('Raw Data'!J33="",0,'Raw Data'!J33) -> 516.66667 | F18: =IF('Raw Data'!K33="",0,'Raw Data'!K33) -> 516.66667 | G18: =IF('Raw Data'!L33="",0,'Raw Data'!L33) -> 516.66667 | H18: =IF('Raw Data'!M33="",0,'Raw Data'!M33) -> 516.66667 | I18: =IF('Raw Data'!N33="",0,'Raw Data'!N33) -> 516.66667 | ... BN18: =IF('Raw Data'!BS33="",0,'Raw Data'!BS33) -> 0 | BO18: =FALSE() -> FALSE
A19: ='Raw Data'!A34 -> Local Account #24 from PA | B19: =IF('Raw Data'!G34="",0,'Raw Data'!G34) -> 0 | C19: =IF('Raw Data'!H34="",0,'Raw Data'!H34) -> 0 | D19: =IF('Raw Data'!I34="",0,'Raw Data'!I34) -> 0 | E19: =IF('Raw Data'!J34="",0,'Raw Data'!J34) -> 0 | F19: =IF('Raw Data'!K34="",0,'Raw Data'!K34) -> 0 | G19: =IF('Raw Data'!L34="",0,'Raw Data'!L34) -> 0 | H19: =IF('Raw Data'!M34="",0,'Raw Data'!M34) -> 125 | I19: =IF('Raw Data'!N34="",0,'Raw Data'!N34) -> 125 | ... BN19: =IF('Raw Data'!BS34="",0,'Raw Data'!BS34) -> 125 | BO19: =FALSE() -> FALSE
A20: ='Raw Data'!A35 -> Local Account #25 from AZ | B20: =IF('Raw Data'!G35="",0,'Raw Data'!G35) -> 437.5 | C20: =IF('Raw Data'!H35="",0,'Raw Data'!H35) -> 437.5 | D20: =IF('Raw Data'!I35="",0,'Raw Data'!I35) -> 437.5 | E20: =IF('Raw Data'!J35="",0,'Raw Data'!J35) -> 437.5 | F20: =IF('Raw Data'!K35="",0,'Raw Data'!K35) -> 437.5 | G20: =IF('Raw Data'!L35="",0,'Raw Data'!L35) -> 437.5 | H20: =IF('Raw Data'!M35="",0,'Raw Data'!M35) -> 437.5 | I20: =IF('Raw Data'!N35="",0,'Raw Data'!N35) -> 437.5 | ... BN20: =IF('Raw Data'!BS35="",0,'Raw Data'!BS35) -> 0 | BO20: =FALSE() -> FALSE
A21: ='Raw Data'!A36 -> Local Account #26 from MI | B21: =IF('Raw Data'!G36="",0,'Raw Data'!G36) -> 600 | C21: =IF('Raw Data'!H36="",0,'Raw Data'!H36) -> 600 | D21: =IF('Raw Data'!I36="",0,'Raw Data'!I36) -> 600 | E21: =IF('Raw Data'!J36="",0,'Raw Data'!J36) -> 600 | F21: =IF('Raw Data'!K36="",0,'Raw Data'!K36) -> 600 | G21: =IF('Raw Data'!L36="",0,'Raw Data'!L36) -> 600 | H21: =IF('Raw Data'!M36="",0,'Raw Data'!M36) -> 600 | I21: =IF('Raw Data'!N36="",0,'Raw Data'!N36) -> 600 | ... BN21: =IF('Raw Data'!BS36="",0,'Raw Data'!BS36) -> 0 | BO21: =FALSE() -> FALSE
A22: ='Raw Data'!A37 -> Local Account #27 from CA | B22: =IF('Raw Data'!G37="",0,'Raw Data'!G37) -> 400 | C22: =IF('Raw Data'!H37="",0,'Raw Data'!H37) -> 400 | D22: =IF('Raw Data'!I37="",0,'Raw Data'!I37) -> 400 | E22: =IF('Raw Data'!J37="",0,'Raw Data'!J37) -> 400 | F22: =IF('Raw Data'!K37="",0,'Raw Data'!K37) -> 400 | G22: =IF('Raw Data'!L37="",0,'Raw Data'!L37) -> 400 | H22: =IF('Raw Data'!M37="",0,'Raw Data'!M37) -> 400 | I22: =IF('Raw Data'!N37="",0,'Raw Data'!N37) -> 400 | ... BN22: =IF('Raw Data'!BS37="",0,'Raw Data'!BS37) -> 900 | BO22: =FALSE() -> FALSE
A23: ='Raw Data'!A38 -> Local Account #28 from CA | B23: =IF('Raw Data'!G38="",0,'Raw Data'!G38) -> 2725 | C23: =IF('Raw Data'!H38="",0,'Raw Data'!H38) -> 2725 | D23: =IF('Raw Data'!I38="",0,'Raw Data'!I38) -> 2725 | E23: =IF('Raw Data'!J38="",0,'Raw Data'!J38) -> 2725 | F23: =IF('Raw Data'!K38="",0,'Raw Data'!K38) -> 2725 | G23: =IF('Raw Data'!L38="",0,'Raw Data'!L38) -> 2725 | H23: =IF('Raw Data'!M38="",0,'Raw Data'!M38) -> 900 | I23: =IF('Raw Data'!N38="",0,'Raw Data'!N38) -> 900 | ... BN23: =IF('Raw Data'!BS38="",0,'Raw Data'!BS38) -> 150 | BO23: =FALSE() -> FALSE
A24: ='Raw Data'!A39 -> Local Account #29 from CA | B24: =IF('Raw Data'!G39="",0,'Raw Data'!G39) -> 0 | C24: =IF('Raw Data'!H39="",0,'Raw Data'!H39) -> 0 | D24: =IF('Raw Data'!I39="",0,'Raw Data'!I39) -> 0 | E24: =IF('Raw Data'!J39="",0,'Raw Data'!J39) -> 0 | F24: =IF('Raw Data'!K39="",0,'Raw Data'!K39) -> 0 | G24: =IF('Raw Data'!L39="",0,'Raw Data'!L39) -> 0 | H24: =IF('Raw Data'!M39="",0,'Raw Data'!M39) -> 0 | I24: =IF('Raw Data'!N39="",0,'Raw Data'!N39) -> 0 | ... BN24: =IF('Raw Data'!BS39="",0,'Raw Data'!BS39) -> 15383.333 | BO24: =FALSE() -> FALSE
A25: ='Raw Data'!A14 -> Local Account #3 from MI | B25: =IF('Raw Data'!G14="",0,'Raw Data'!G14) -> 0 | C25: =IF('Raw Data'!H14="",0,'Raw Data'!H14) -> 0 | D25: =IF('Raw Data'!I14="",0,'Raw Data'!I14) -> 0 | E25: =IF('Raw Data'!J14="",0,'Raw Data'!J14) -> 0 | F25: =IF('Raw Data'!K14="",0,'Raw Data'!K14) -> 0 | G25: =IF('Raw Data'!L14="",0,'Raw Data'!L14) -> 0 | H25: =IF('Raw Data'!M14="",0,'Raw Data'!M14) -> 0 | I25: =IF('Raw Data'!N14="",0,'Raw Data'!N14) -> 0 | ... BN25: =IF('Raw Data'!BS14="",0,'Raw Data'!BS14) -> 13239.583 | BO25: =FALSE() -> FALSE
A26: ='Raw Data'!A40 -> Local Account #30 from OR | B26: =IF('Raw Data'!G40="",0,'Raw Data'!G40) -> 0 | C26: =IF('Raw Data'!H40="",0,'Raw Data'!H40) -> 0 | D26: =IF('Raw Data'!I40="",0,'Raw Data'!I40) -> 0 | E26: =IF('Raw Data'!J40="",0,'Raw Data'!J40) -> 0 | F26: =IF('Raw Data'!K40="",0,'Raw Data'!K40) -> 0 | G26: =IF('Raw Data'!L40="",0,'Raw Data'!L40) -> 0 | H26: =IF('Raw Data'!M40="",0,'Raw Data'!M40) -> 0 | I26: =IF('Raw Data'!N40="",0,'Raw Data'!N40) -> 0 | ... BN26: =IF('Raw Data'!BS40="",0,'Raw Data'!BS40) -> 137.5 | BO26: =FALSE() -> FALSE
A27: ='Raw Data'!A41 -> Local Account #31 from CA | B27: =IF('Raw Data'!G41="",0,'Raw Data'!G41) -> 0 | C27: =IF('Raw Data'!H41="",0,'Raw Data'!H41) -> 0 | D27: =IF('Raw Data'!I41="",0,'Raw Data'!I41) -> 0 | E27: =IF('Raw Data'!J41="",0,'Raw Data'!J41) -> 0 | F27: =IF('Raw Data'!K41="",0,'Raw Data'!K41) -> 0 | G27: =IF('Raw Data'!L41="",0,'Raw Data'!L41) -> 0 | H27: =IF('Raw Data'!M41="",0,'Raw Data'!M41) -> 0 | I27: =IF('Raw Data'!N41="",0,'Raw Data'!N41) -> 0 | ... BN27: =IF('Raw Data'!BS41="",0,'Raw Data'!BS41) -> 1500 | BO27: =FALSE() -> FALSE
A28: ='Raw Data'!A42 -> Local Account #32 from CA | B28: =IF('Raw Data'!G42="",0,'Raw Data'!G42) -> 0 | C28: =IF('Raw Data'!H42="",0,'Raw Data'!H42) -> 0 | D28: =IF('Raw Data'!I42="",0,'Raw Data'!I42) -> 0 | E28: =IF('Raw Data'!J42="",0,'Raw Data'!J42) -> 0 | F28: =IF('Raw Data'!K42="",0,'Raw Data'!K42) -> 0 | G28: =IF('Raw Data'!L42="",0,'Raw Data'!L42) -> 0 | H28: =IF('Raw Data'!M42="",0,'Raw Data'!M42) -> 0 | I28: =IF('Raw Data'!N42="",0,'Raw Data'!N42) -> 0 | ... BN28: =IF('Raw Data'!BS42="",0,'Raw Data'!BS42) -> 122.2225 | BO28: =FALSE() -> FALSE
A29: ='Raw Data'!A43 -> Local Account #33 from CA | B29: =IF('Raw Data'!G43="",0,'Raw Data'!G43) -> 0 | C29: =IF('Raw Data'!H43="",0,'Raw Data'!H43) -> 0 | D29: =IF('Raw Data'!I43="",0,'Raw Data'!I43) -> 0 | E29: =IF('Raw Data'!J43="",0,'Raw Data'!J43) -> 0 | F29: =IF('Raw Data'!K43="",0,'Raw Data'!K43) -> 0 | G29: =IF('Raw Data'!L43="",0,'Raw Data'!L43) -> 0 | H29: =IF('Raw Data'!M43="",0,'Raw Data'!M43) -> 0 | I29: =IF('Raw Data'!N43="",0,'Raw Data'!N43) -> 0 | ... BN29: =IF('Raw Data'!BS43="",0,'Raw Data'!BS43) -> 1266.6667 | BO29: =FALSE() -> FALSE
A30: ='Raw Data'!A44 -> Local Account #34 from MI | B30: =IF('Raw Data'!G44="",0,'Raw Data'!G44) -> 12737.983 | C30: =IF('Raw Data'!H44="",0,'Raw Data'!H44) -> 12737.983 | D30: =IF('Raw Data'!I44="",0,'Raw Data'!I44) -> 12737.983 | E30: =IF('Raw Data'!J44="",0,'Raw Data'!J44) -> 12737.983 | F30: =IF('Raw Data'!K44="",0,'Raw Data'!K44) -> 12737.983 | G30: =IF('Raw Data'!L44="",0,'Raw Data'!L44) -> 12737.983 | H30: =IF('Raw Data'!M44="",0,'Raw Data'!M44) -> 14875.483 | I30: =IF('Raw Data'!N44="",0,'Raw Data'!N44) -> 14875.483 | ... BN30: =IF('Raw Data'!BS44="",0,'Raw Data'!BS44) -> 20475 | BO30: =FALSE() -> FALSE
A31: ='Raw Data'!A45 -> Local Account #35 from OR | B31: =IF('Raw Data'!G45="",0,'Raw Data'!G45) -> 0 | C31: =IF('Raw Data'!H45="",0,'Raw Data'!H45) -> 0 | D31: =IF('Raw Data'!I45="",0,'Raw Data'!I45) -> 0 | E31: =IF('Raw Data'!J45="",0,'Raw Data'!J45) -> 0 | F31: =IF('Raw Data'!K45="",0,'Raw Data'!K45) -> 0 | G31: =IF('Raw Data'!L45="",0,'Raw Data'!L45) -> 0 | H31: =IF('Raw Data'!M45="",0,'Raw Data'!M45) -> 0 | I31: =IF('Raw Data'!N45="",0,'Raw Data'!N45) -> 0 | ... BN31: =IF('Raw Data'!BS45="",0,'Raw Data'!BS45) -> 122.66667 | BO31: =FALSE() -> FALSE
A32: ='Raw Data'!A46 -> Local Account #36 from CA | B32: =IF('Raw Data'!G46="",0,'Raw Data'!G46) -> 2537.5 | C32: =IF('Raw Data'!H46="",0,'Raw Data'!H46) -> 2537.5 | D32: =IF('Raw Data'!I46="",0,'Raw Data'!I46) -> 1280 | E32: =IF('Raw Data'!J46="",0,'Raw Data'!J46) -> 1280 | F32: =IF('Raw Data'!K46="",0,'Raw Data'!K46) -> 1280 | G32: =IF('Raw Data'!L46="",0,'Raw Data'!L46) -> 1280 | H32: =IF('Raw Data'!M46="",0,'Raw Data'!M46) -> 1280 | I32: =IF('Raw Data'!N46="",0,'Raw Data'!N46) -> 1280 | ... BN32: =IF('Raw Data'!BS46="",0,'Raw Data'!BS46) -> 0 | BO32: =FALSE() -> FALSE
A33: ='Raw Data'!A47 -> Local Account #37 from NC | B33: =IF('Raw Data'!G47="",0,'Raw Data'!G47) -> 0 | C33: =IF('Raw Data'!H47="",0,'Raw Data'!H47) -> 0 | D33: =IF('Raw Data'!I47="",0,'Raw Data'!I47) -> 0 | E33: =IF('Raw Data'!J47="",0,'Raw Data'!J47) -> 0 | F33: =IF('Raw Data'!K47="",0,'Raw Data'!K47) -> 0 | G33: =IF('Raw Data'!L47="",0,'Raw Data'!L47) -> 0 | H33: =IF('Raw Data'!M47="",0,'Raw Data'!M47) -> 0 | I33: =IF('Raw Data'!N47="",0,'Raw Data'!N47) -> 0 | ... BN33: =IF('Raw Data'!BS47="",0,'Raw Data'!BS47) -> 0 | BO33: =FALSE() -> FALSE
A34: ='Raw Data'!A48 -> Local Account #38 from CA | B34: =IF('Raw Data'!G48="",0,'Raw Data'!G48) -> 1466.6753 | C34: =IF('Raw Data'!H48="",0,'Raw Data'!H48) -> 1466.6753 | D34: =IF('Raw Data'!I48="",0,'Raw Data'!I48) -> 1466.6753 | E34: =IF('Raw Data'!J48="",0,'Raw Data'!J48) -> 1466.6753 | F34: =IF('Raw Data'!K48="",0,'Raw Data'!K48) -> 1466.6753 | G34: =IF('Raw Data'!L48="",0,'Raw Data'!L48) -> 1466.6667 | H34: =IF('Raw Data'!M48="",0,'Raw Data'!M48) -> 1800.0167 | I34: =IF('Raw Data'!N48="",0,'Raw Data'!N48) -> 1800.0167 | ... BN34: =IF('Raw Data'!BS48="",0,'Raw Data'!BS48) -> 5426.6133 | BO34: =FALSE() -> FALSE
A35: ='Raw Data'!A49 -> Local Account #39 from CA | B35: =IF('Raw Data'!G49="",0,'Raw Data'!G49) -> 0 | C35: =IF('Raw Data'!H49="",0,'Raw Data'!H49) -> 0 | D35: =IF('Raw Data'!I49="",0,'Raw Data'!I49) -> 0 | E35: =IF('Raw Data'!J49="",0,'Raw Data'!J49) -> 0 | F35: =IF('Raw Data'!K49="",0,'Raw Data'!K49) -> 0 | G35: =IF('Raw Data'!L49="",0,'Raw Data'!L49) -> 0 | H35: =IF('Raw Data'!M49="",0,'Raw Data'!M49) -> 0 | I35: =IF('Raw Data'!N49="",0,'Raw Data'!N49) -> 0 | ... BN35: =IF('Raw Data'!BS49="",0,'Raw Data'!BS49) -> 0 | BO35: =FALSE() -> FALSE
A36: ='Raw Data'!A15 -> Local Account #4 from CA | B36: =IF('Raw Data'!G15="",0,'Raw Data'!G15) -> 0 | C36: =IF('Raw Data'!H15="",0,'Raw Data'!H15) -> 0 | D36: =IF('Raw Data'!I15="",0,'Raw Data'!I15) -> 0 | E36: =IF('Raw Data'!J15="",0,'Raw Data'!J15) -> 0 | F36: =IF('Raw Data'!K15="",0,'Raw Data'!K15) -> 0 | G36: =IF('Raw Data'!L15="",0,'Raw Data'!L15) -> 0 | H36: =IF('Raw Data'!M15="",0,'Raw Data'!M15) -> 0 | I36: =IF('Raw Data'!N15="",0,'Raw Data'!N15) -> 0 | ... BN36: =IF('Raw Data'!BS15="",0,'Raw Data'!BS15) -> 5613.5 | BO36: =FALSE() -> FALSE
A37: ='Raw Data'!A50 -> Local Account #40 from OH | B37: =IF('Raw Data'!G50="",0,'Raw Data'!G50) -> 0 | C37: =IF('Raw Data'!H50="",0,'Raw Data'!H50) -> 0 | D37: =IF('Raw Data'!I50="",0,'Raw Data'!I50) -> 0 | E37: =IF('Raw Data'!J50="",0,'Raw Data'!J50) -> 0 | F37: =IF('Raw Data'!K50="",0,'Raw Data'!K50) -> 0 | G37: =IF('Raw Data'!L50="",0,'Raw Data'!L50) -> 0 | H37: =IF('Raw Data'!M50="",0,'Raw Data'!M50) -> 0 | I37: =IF('Raw Data'!N50="",0,'Raw Data'!N50) -> 0 | ... BN37: =IF('Raw Data'!BS50="",0,'Raw Data'!BS50) -> 0 | BO37: =FALSE() -> FALSE
A38: ='Raw Data'!A51 -> Local Account #41 from CA | B38: =IF('Raw Data'!G51="",0,'Raw Data'!G51) -> 2108.3333 | C38: =IF('Raw Data'!H51="",0,'Raw Data'!H51) -> 2941.6675 | D38: =IF('Raw Data'!I51="",0,'Raw Data'!I51) -> 2941.6675 | E38: =IF('Raw Data'!J51="",0,'Raw Data'!J51) -> 2941.6675 | F38: =IF('Raw Data'!K51="",0,'Raw Data'!K51) -> 2941.6675 | G38: =IF('Raw Data'!L51="",0,'Raw Data'!L51) -> 2941.6675 | H38: =IF('Raw Data'!M51="",0,'Raw Data'!M51) -> 2941.6675 | I38: =IF('Raw Data'!N51="",0,'Raw Data'!N51) -> 2941.6675 | ... BN38: =IF('Raw Data'!BS51="",0,'Raw Data'!BS51) -> 1108.3333 | BO38: =FALSE() -> FALSE
A39: ='Raw Data'!A53 -> Local Account #43 from VA | B39: =IF('Raw Data'!G53="",0,'Raw Data'!G53) -> 0 | C39: =IF('Raw Data'!H53="",0,'Raw Data'!H53) -> 0 | D39: =IF('Raw Data'!I53="",0,'Raw Data'!I53) -> 0 | E39: =IF('Raw Data'!J53="",0,'Raw Data'!J53) -> 0 | F39: =IF('Raw Data'!K53="",0,'Raw Data'!K53) -> 0 | G39: =IF('Raw Data'!L53="",0,'Raw Data'!L53) -> 0 | H39: =IF('Raw Data'!M53="",0,'Raw Data'!M53) -> 0 | I39: =IF('Raw Data'!N53="",0,'Raw Data'!N53) -> 0 | ... BN39: =IF('Raw Data'!BS53="",0,'Raw Data'!BS53) -> 0 | BO39: =FALSE() -> FALSE
A40: ='Raw Data'!A54 -> Local Account #44 from CA | B40: =IF('Raw Data'!G54="",0,'Raw Data'!G54) -> 0 | C40: =IF('Raw Data'!H54="",0,'Raw Data'!H54) -> 0 | D40: =IF('Raw Data'!I54="",0,'Raw Data'!I54) -> 0 | E40: =IF('Raw Data'!J54="",0,'Raw Data'!J54) -> 0 | F40: =IF('Raw Data'!K54="",0,'Raw Data'!K54) -> 0 | G40: =IF('Raw Data'!L54="",0,'Raw Data'!L54) -> 0 | H40: =IF('Raw Data'!M54="",0,'Raw Data'!M54) -> 0 | I40: =IF('Raw Data'!N54="",0,'Raw Data'!N54) -> 0 | ... BN40: =IF('Raw Data'!BS54="",0,'Raw Data'!BS54) -> 2060 | BO40: =FALSE() -> FALSE
A41: ='Raw Data'!A55 -> Local Account #45 from TX | B41: =IF('Raw Data'!G55="",0,'Raw Data'!G55) -> 0 | C41: =IF('Raw Data'!H55="",0,'Raw Data'!H55) -> 0 | D41: =IF('Raw Data'!I55="",0,'Raw Data'!I55) -> 0 | E41: =IF('Raw Data'!J55="",0,'Raw Data'!J55) -> 0 | F41: =IF('Raw Data'!K55="",0,'Raw Data'!K55) -> 0 | G41: =IF('Raw Data'!L55="",0,'Raw Data'!L55) -> 0 | H41: =IF('Raw Data'!M55="",0,'Raw Data'!M55) -> 0 | I41: =IF('Raw Data'!N55="",0,'Raw Data'!N55) -> 0 | ... BN41: =IF('Raw Data'!BS55="",0,'Raw Data'!BS55) -> 0 | BO41: =FALSE() -> FALSE
A42: ='Raw Data'!A56 -> Local Account #46 from CA | B42: =IF('Raw Data'!G56="",0,'Raw Data'!G56) -> 800 | C42: =IF('Raw Data'!H56="",0,'Raw Data'!H56) -> 800 | D42: =IF('Raw Data'!I56="",0,'Raw Data'!I56) -> 800 | E42: =IF('Raw Data'!J56="",0,'Raw Data'!J56) -> 1000 | F42: =IF('Raw Data'!K56="",0,'Raw Data'!K56) -> 1000 | G42: =IF('Raw Data'!L56="",0,'Raw Data'!L56) -> 1000 | H42: =IF('Raw Data'!M56="",0,'Raw Data'!M56) -> 1000 | I42: =IF('Raw Data'!N56="",0,'Raw Data'!N56) -> 1000 | ... BN42: =IF('Raw Data'!BS56="",0,'Raw Data'!BS56) -> 900 | BO42: =FALSE() -> FALSE
A43: ='Raw Data'!A57 -> Local Account #47 from NY | B43: =IF('Raw Data'!G57="",0,'Raw Data'!G57) -> 291.66667 | C43: =IF('Raw Data'!H57="",0,'Raw Data'!H57) -> 291.66667 | D43: =IF('Raw Data'!I57="",0,'Raw Data'!I57) -> 291.66667 | E43: =IF('Raw Data'!J57="",0,'Raw Data'!J57) -> 291.66667 | F43: =IF('Raw Data'!K57="",0,'Raw Data'!K57) -> 291.66667 | G43: =IF('Raw Data'!L57="",0,'Raw Data'!L57) -> 291.66667 | H43: =IF('Raw Data'!M57="",0,'Raw Data'!M57) -> 291.66667 | I43: =IF('Raw Data'!N57="",0,'Raw Data'!N57) -> 291.66667 | ... BN43: =IF('Raw Data'!BS57="",0,'Raw Data'!BS57) -> 350 | BO43: =FALSE() -> FALSE
A44: ='Raw Data'!A58 -> Local Account #48 from IL | B44: =IF('Raw Data'!G58="",0,'Raw Data'!G58) -> 0 | C44: =IF('Raw Data'!H58="",0,'Raw Data'!H58) -> 0 | D44: =IF('Raw Data'!I58="",0,'Raw Data'!I58) -> 0 | E44: =IF('Raw Data'!J58="",0,'Raw Data'!J58) -> 0 | F44: =IF('Raw Data'!K58="",0,'Raw Data'!K58) -> 0 | G44: =IF('Raw Data'!L58="",0,'Raw Data'!L58) -> 0 | H44: =IF('Raw Data'!M58="",0,'Raw Data'!M58) -> 5100 | I44: =IF('Raw Data'!N58="",0,'Raw Data'!N58) -> 5100 | ... BN44: =IF('Raw Data'!BS58="",0,'Raw Data'!BS58) -> 1700 | BO44: =FALSE() -> FALSE
A45: ='Raw Data'!A59 -> Local Account #49 from KY | B45: =IF('Raw Data'!G59="",0,'Raw Data'!G59) -> 0 | C45: =IF('Raw Data'!H59="",0,'Raw Data'!H59) -> 0 | D45: =IF('Raw Data'!I59="",0,'Raw Data'!I59) -> 0 | E45: =IF('Raw Data'!J59="",0,'Raw Data'!J59) -> 0 | F45: =IF('Raw Data'!K59="",0,'Raw Data'!K59) -> 0 | G45: =IF('Raw Data'!L59="",0,'Raw Data'!L59) -> 0 | H45: =IF('Raw Data'!M59="",0,'Raw Data'!M59) -> 0 | I45: =IF('Raw Data'!N59="",0,'Raw Data'!N59) -> 0 | ... BN45: =IF('Raw Data'!BS59="",0,'Raw Data'!BS59) -> 16970 | BO45: =FALSE() -> FALSE
A46: ='Raw Data'!A16 -> Local Account #5 from OH | B46: =IF('Raw Data'!G16="",0,'Raw Data'!G16) -> 0 | C46: =IF('Raw Data'!H16="",0,'Raw Data'!H16) -> 0 | D46: =IF('Raw Data'!I16="",0,'Raw Data'!I16) -> 0 | E46: =IF('Raw Data'!J16="",0,'Raw Data'!J16) -> 0 | F46: =IF('Raw Data'!K16="",0,'Raw Data'!K16) -> 0 | G46: =IF('Raw Data'!L16="",0,'Raw Data'!L16) -> 0 | H46: =IF('Raw Data'!M16="",0,'Raw Data'!M16) -> 0 | I46: =IF('Raw Data'!N16="",0,'Raw Data'!N16) -> 0 | ... BN46: =IF('Raw Data'!BS16="",0,'Raw Data'!BS16) -> 825 | BO46: =FALSE() -> FALSE
A47: ='Raw Data'!A60 -> Local Account #50 from MI | B47: =IF('Raw Data'!G60="",0,'Raw Data'!G60) -> 5295.8333 | C47: =IF('Raw Data'!H60="",0,'Raw Data'!H60) -> 5618.7333 | D47: =IF('Raw Data'!I60="",0,'Raw Data'!I60) -> 5618.7333 | E47: =IF('Raw Data'!J60="",0,'Raw Data'!J60) -> 5618.7333 | F47: =IF('Raw Data'!K60="",0,'Raw Data'!K60) -> 5618.7333 | G47: =IF('Raw Data'!L60="",0,'Raw Data'!L60) -> 5618.7333 | H47: =IF('Raw Data'!M60="",0,'Raw Data'!M60) -> 5618.7333 | I47: =IF('Raw Data'!N60="",0,'Raw Data'!N60) -> 5618.7333 | ... BN47: =IF('Raw Data'!BS60="",0,'Raw Data'!BS60) -> 3333.3333 | BO47: =FALSE() -> FALSE
A48: ='Raw Data'!A61 -> Local Account #51 from CA | B48: =IF('Raw Data'!G61="",0,'Raw Data'!G61) -> 1866.47 | C48: =IF('Raw Data'!H61="",0,'Raw Data'!H61) -> 1866.47 | D48: =IF('Raw Data'!I61="",0,'Raw Data'!I61) -> 1866.47 | E48: =IF('Raw Data'!J61="",0,'Raw Data'!J61) -> 1866.47 | F48: =IF('Raw Data'!K61="",0,'Raw Data'!K61) -> 1866.47 | G48: =IF('Raw Data'!L61="",0,'Raw Data'!L61) -> 1866.47 | H48: =IF('Raw Data'!M61="",0,'Raw Data'!M61) -> 50 | I48: =IF('Raw Data'!N61="",0,'Raw Data'!N61) -> 50 | ... BN48: =IF('Raw Data'!BS61="",0,'Raw Data'!BS61) -> 0 | BO48: =FALSE() -> FALSE
...

Sheet Raw Data
G1: Unadj. | H1: Unadj. | I1: Unadj. | J1: Unadj. | K1: Unadj. | L1: Unadj. | M1: Unadj. | N1: Unadj. | O1: Unadj. | P1: Unadj. | Q1: Unadj. | R1: Unadj. | S1: Unadj. | T1: Unadj. | U1: Unadj. | V1: Unadj. | W1: Unadj. | X1: Unadj. | Y1: Unadj. | Z1: Unadj. | AA1: Unadj. | AB1: Unadj. | AC1: Unadj. | AD1: Unadj. | AE1: Unadj. | AF1: Unadj. | AG1: Unadj. | AH1: Unadj. | AI1: Unadj. | AJ1: Unadj. | AK1: Unadj. | AL1: Unadj. | AM1: Unadj. | AN1: Unadj. | AO1: Unadj. | AP1: Unadj. | AQ1: Unadj. | AR1: Unadj. | AS1: Unadj. | AT1: Unadj. | AU1: Unadj. | AV1: Unadj. | AW1: Unadj. | AX1: Unadj. | AY1: Unadj. | AZ1: Unadj. | BA1: Unadj. | BB1: Unadj. | BC1: Unadj. | BD1: Unadj. | BE1: Unadj. | BF1: Unadj. | BG1: Unadj. | BH1: Unadj. | BI1: Unadj. | BJ1: Unadj. | BK1: Unadj. | BL1: Unadj. | BM1: Unadj. | BN1: Unadj. | BO1: Unadj. | BP1: Unadj. | BQ1: Unadj. | BR1: Unadj. | BS1: Unadj. | BT1: Unadj. | BU1: Unadj. | BV1: Unadj. | BW1: Unadj. | BX1: Unadj. | BY1: Unadj. | BZ1: Unadj. | CC1: Adjustment | CD1: Adjustment | CE1: Adjustment | CF1: Adjustment | CG1: Adjustment | CH1: Adjustment | CI1: Adjustment | CJ1: Adjustment | CK1: Adjustment | CL1: Adjustment | CM1: Adjustment | CN1: Adjustment | CO1: Adjustment | CP1: Adjustment | CQ1: Adjustment | CR1: Adjustment | CS1: Adjustment | CT1: Adjustment | CU1: Adjustment | CV1: Adjustment | CW1: Adjustment | CX1: Adjustment | CY1: Adjustment | CZ1: Adjustment | DA1: Adjustment | DB1: Adjustment | DC1: Adjustment | DD1: Adjustment | DE1: Adjustment | DF1: Adjustment | DG1: Adjustment | DH1: Adjustment | DI1: Adjustment | DJ1: Adjustment | DK1: Adjustment | DL1: Adjustment | DM1: Adjustment | DN1: Adjustment | DO1: Adjustment | DP1: Adjustment | DQ1: Adjustment | DR1: Adjustment | DS1: Adjustment | DT1: Adjustment | DU1: Adjustment | DV1: Adjustment | DW1: Adjustment | DX1: Adjustment | DY1: Adjustment | DZ1: Adjustment | EA1: Adjustment | EB1: Adjustment | EC1: Adjustment | ED1: Adjustment | EE1: Adjustment | EF1: Adjustment | EG1: Adjustment | EH1: Adjustment | EI1: Adjustment | EJ1: Adjustment | EK1: Adjustment | EL1: Adjustment | EM1: Adjustment | EN1: Adjustment | EO1: Adjustment | EP1: Adjustment | EQ1: Adjustment | ER1: Adjustment | ES1: Adjustment | ET1: Adjustment | EU1: Adjustment | EV1: Adjustment | EX1: Adj. for promotions, co-development and never live churn | EY1: Adj. for promotions, co-development and never live churn | EZ1: Adj. for promotions, co-development and never live churn | FA1: Adj. for promotions, co-development and never live churn | FB1: Adj. for promotions, co-development and never live churn | FC1: Adj. for promotions, co-development and never live churn | FD1: Adj. for promotions, co-development and never live churn | FE1: Adj. for promotions, co-development and never live churn | FF1: Adj. for promotions, co-development and never live churn | FG1: Adj. for promotions, co-development and never live churn | FH1: Adj. for promotions, co-development and never live churn | FI1: Adj. for promotions, co-development and never live churn | FJ1: Adj. for promotions, co-development and never live churn | FK1: Adj. for promotions, co-development and never live churn | FL1: Adj. for promotions, co-development and never live churn | FM1: Adj. for promotions, co-development and never live churn | FN1: Adj. for promotions, co-development and never live churn | FO1: Adj. for promotions, co-development and never live churn | FP1: Adj. for promotions, co-development and never live churn | FQ1: Adj. for promotions, co-development and never live churn | FR1: Adj. for promotions, co-development and never live churn | FS1: Adj. for promotions, co-development and never live churn | FT1: Adj. for promotions, co-development and never live churn | FU1: Adj. for promotions, co-development and never live churn | FV1: Adj. for promotions, co-development and never live churn | FW1: Adj. for promotions, co-development and never live churn | FX1: Adj. for promotions, co-development and never live churn | FY1: Adj. for promotions, co-development and never live churn | FZ1: Adj. for promotions, co-development and never live churn | GA1: Adj. for promotions, co-development and never live churn | GB1: Adj. for promotions, co-development and never live churn | GC1: Adj. for promotions, co-development and never live churn | GD1: Adj. for promotions, co-development and never live churn | GE1: Adj. for promotions, co-development and never live churn | GF1: Adj. for promotions, co-development and never live churn | GG1: Adj. for promotions, co-development and never live churn | GH1: Adj. for promotions, co-development and never live churn | GI1: Adj. for promotions, co-development and never live churn | GJ1: Adj. for promotions, co-development and never live churn | GK1: Adj. for promotions, co-development and never live churn | GL1: Adj. for promotions, co-development and never live churn | GM1: Adj. for promotions, co-development and never live churn | GN1: Adj. for promotions, co-development and never live churn | GO1: Adj. for promotions, co-development and never live churn | GP1: Adj. for promotions, co-development and never live churn | GQ1: Adj. for promotions, co-development and never live churn | GR1: Adj. for promotions, co-development and never live churn | GS1: Adj. for promotions, co-development and never live churn | GT1: Adj. for promotions, co-development and never live churn | GU1: Adj. for promotions, co-development and never live churn | GV1: Adj. for promotions, co-development and never live churn | GW1: Adj. for promotions, co-development and never live churn | GX1: Adj. for promotions, co-development and never live churn | GY1: Adj. for promotions, co-development and never live churn | GZ1: Adj. for promotions, co-development and never live churn | HA1: Adj. for promotions, co-development and never live churn | HB1: Adj. for promotions, co-development and never live churn | HC1: Adj. for promotions, co-development and never live churn | HD1: Adj. for promotions, co-development and never live churn | HE1: Adj. for promotions, co-development and never live churn | HF1: Adj. for promotions, co-development and never live churn | HG1: Adj. for promotions, co-development and never live churn | HH1: Adj. for promotions, co-development and never live churn | HI1: Adj. for promotions, co-development and never live churn | HJ1: Adj. for promotions, co-development and never live churn | HK1: Adj. for promotions, co-development and never live churn | HL1: Adj. for promotions, co-development and never live churn | HM1: Adj. for promotions, co-development and never live churn | HN1: Adj. for promotions, co-development and never live churn | HO1: Adj. for promotions, co-development and never live churn | HP1: Adj. for promotions, co-development and never live churn | HQ1: Adj. for promotions, co-development and never live churn | HS1: Adj. for all involuntary churn | HT1: Adj. for all involuntary churn | HU1: Adj. for all involuntary churn | HV1: Adj. for all involuntary churn | HW1: Adj. for all involuntary churn | HX1: Adj. for all involuntary churn | HY1: Adj. for all involuntary churn | HZ1: Adj. for all involuntary churn | IA1: Adj. for all involuntary churn | IB1: Adj. for all involuntary churn | IC1: Adj. for all involuntary churn | ID1: Adj. for all involuntary churn | IE1: Adj. for all involuntary churn | IF1: Adj. for all involuntary churn | IG1: Adj. for all involuntary churn | IH1: Adj. for all involuntary churn | II1: Adj. for all involuntary churn | IJ1: Adj. for all involuntary churn | IK1: Adj. for all involuntary churn | IL1: Adj. for all involuntary churn | IM1: Adj. for all involuntary churn | IN1: Adj. for all involuntary churn | IO1: Adj. for all involuntary churn | IP1: Adj. for all involuntary churn | IQ1: Adj. for all involuntary churn | IR1: Adj. for all involuntary churn | IS1: Adj. for all involuntary churn | IT1: Adj. for all involuntary churn | IU1: Adj. for all involuntary churn | IV1: Adj. for all involuntary churn | IW1: Adj. for all involuntary churn | IX1: Adj. for all involuntary churn | IY1: Adj. for all involuntary churn | IZ1: Adj. for all involuntary churn | JA1: Adj. for all involuntary churn | JB1: Adj. for all involuntary churn | JC1: Adj. for all involuntary churn | JD1: Adj. for all involuntary churn | JE1: Adj. for all involuntary churn | JF1: Adj. for all involuntary churn | JG1: Adj. for all involuntary churn | JH1: Adj. for all involuntary churn | JI1: Adj. for all involuntary churn | JJ1: Adj. for all involuntary churn | JK1: Adj. for all involuntary churn | JL1: Adj. for all involuntary churn | JM1: Adj. for all involuntary churn | JN1: Adj. for all involuntary churn | JO1: Adj. for all involuntary churn | JP1: Adj. for all involuntary churn | JQ1: Adj. for all involuntary churn | JR1: Adj. for all involuntary churn | JS1: Adj. for all involuntary churn | JT1: Adj. for all involuntary churn | JU1: Adj. for all involuntary churn | JV1: Adj. for all involuntary churn | JW1: Adj. for all involuntary churn | JX1: Adj. for all involuntary churn | JY1: Adj. for all involuntary churn | JZ1: Adj. for all involuntary churn | KA1: Adj. for all involuntary churn | KB1: Adj. for all involuntary churn | KC1: Adj. for all involuntary churn | KD1: Adj. for all involuntary churn | KE1: Adj. for all involuntary churn | KF1: Adj. for all involuntary churn | KG1: Adj. for all involuntary churn | KH1: Adj. for all involuntary churn | KI1: Adj. for all involuntary churn | KJ1: Adj. for all involuntary churn | KK1: Adj. for all involuntary churn | KL1: Adj. for all involuntary churn
G2: 2021 | H2: 2021 | I2: 2021 | J2: 2021 | K2: 2021 | L2: 2021 | M2: 2021 | N2: 2021 | O2: 2021 | P2: 2021 | Q2: 2021 | R2: 2021 | S2: 2022 | T2: 2022 | U2: 2022 | V2: 2022 | W2: 2022 | X2: 2022 | Y2: 2022 | Z2: 2022 | AA2: 2022 | AB2: 2022 | AC2: 2022 | AD2: 2022 | AE2: 2023 | AF2: 2023 | AG2: 2023 | AH2: 2023 | AI2: 2023 | AJ2: 2023 | AK2: 2023 | AL2: 2023 | AM2: 2023 | AN2: 2023 | AO2: 2023 | AP2: 2023 | AQ2: 2024 | AR2: 2024 | AS2: 2024 | AT2: 2024 | AU2: 2024 | AV2: 2024 | AW2: 2024 | AX2: 2024 | AY2: 2024 | AZ2: 2024 | BA2: 2024 | BB2: 2024 | BC2: 2025 | BD2: 2025 | BE2: 2025 | BF2: 2025 | BG2: 2025 | BH2: 2025 | BI2: 2025 | BJ2: 2025 | BK2: 2025 | BL2: 2025 | BM2: 2025 | BN2: 2025 | BO2: 2026 | BP2: 2026 | BQ2: 2026 | BR2: 2026 | BS2: 2026 | BT2: 2026 | BU2: 2026 | BV2: 2026 | BW2: 2026 | BX2: 2026 | BY2: 2026 | BZ2: 2026 | CC2: 2021 | CD2: 2021 | CE2: 2021 | CF2: 2021 | CG2: 2021 | CH2: 2021 | CI2: 2021 | CJ2: 2021 | CK2: 2021 | CL2: 2021 | CM2: 2021 | CN2: 2021 | CO2: 2022 | CP2: 2022 | CQ2: 2022 | CR2: 2022 | CS2: 2022 | CT2: 2022 | CU2: 2022 | CV2: 2022 | CW2: 2022 | CX2: 2022 | CY2: 2022 | CZ2: 2022 | DA2: 2023 | DB2: 2023 | DC2: 2023 | DD2: 2023 | DE2: 2023 | DF2: 2023 | DG2: 2023 | DH2: 2023 | DI2: 2023 | DJ2: 2023 | DK2: 2023 | DL2: 2023 | DM2: 2024 | DN2: 2024 | DO2: 2024 | DP2: 2024 | DQ2: 2024 | DR2: 2024 | DS2: 2024 | DT2: 2024 | DU2: 2024 | DV2: 2024 | DW2: 2024 | DX2: 2024 | DY2: 2025 | DZ2: 2025 | EA2: 2025 | EB2: 2025 | EC2: 2025 | ED2: 2025 | EE2: 2025 | EF2: 2025 | EG2: 2025 | EH2: 2025 | EI2: 2025 | EJ2: 2025 | EK2: 2026 | EL2: 2026 | EM2: 2026 | EN2: 2026 | EO2: 2026 | EP2: 2026 | EQ2: 2026 | ER2: 2026 | ES2: 2026 | ET2: 2026 | EU2: 2026 | EV2: 2026 | EX2: 2021 | EY2: 2021 | EZ2: 2021 | FA2: 2021 | FB2: 2021 | FC2: 2021 | FD2: 2021 | FE2: 2021 | FF2: 2021 | FG2: 2021 | FH2: 2021 | FI2: 2021 | FJ2: 2022 | FK2: 2022 | FL2: 2022 | FM2: 2022 | FN2: 2022 | FO2: 2022 | FP2: 2022 | FQ2: 2022 | FR2: 2022 | FS2: 2022 | FT2: 2022 | FU2: 2022 | FV2: 2023 | FW2: 2023 | FX2: 2023 | FY2: 2023 | FZ2: 2023 | GA2: 2023 | GB2: 2023 | GC2: 2023 | GD2: 2023 | GE2: 2023 | GF2: 2023 | GG2: 2023 | GH2: 2024 | GI2: 2024 | GJ2: 2024 | GK2: 2024 | GL2: 2024 | GM2: 2024 | GN2: 2024 | GO2: 2024 | GP2: 2024 | GQ2: 2024 | GR2: 2024 | GS2: 2024 | GT2: 2025 | GU2: 2025 | GV2: 2025 | GW2: 2025 | GX2: 2025 | GY2: 2025 | GZ2: 2025 | HA2: 2025 | HB2: 2025 | HC2: 2025 | HD2: 2025 | HE2: 2025 | HF2: 2026 | HG2: 2026 | HH2: 2026 | HI2: 2026 | HJ2: 2026 | HK2: 2026 | HL2: 2026 | HM2: 2026 | HN2: 2026 | HO2: 2026 | HP2: 2026 | HQ2: 2026 | HS2: 2021 | HT2: 2021 | HU2: 2021 | HV2: 2021 | HW2: 2021 | HX2: 2021 | HY2: 2021 | HZ2: 2021 | IA2: 2021 | IB2: 2021 | IC2: 2021 | ID2: 2021 | IE2: 2022 | IF2: 2022 | IG2: 2022 | IH2: 2022 | II2: 2022 | IJ2: 2022 | IK2: 2022 | IL2: 2022 | IM2: 2022 | IN2: 2022 | IO2: 2022 | IP2: 2022 | IQ2: 2023 | IR2: 2023 | IS2: 2023 | IT2: 2023 | IU2: 2023 | IV2: 2023 | IW2: 2023 | IX2: 2023 | IY2: 2023 | IZ2: 2023 | JA2: 2023 | JB2: 2023 | JC2: 2024 | JD2: 2024 | JE2: 2024 | JF2: 2024 | JG2: 2024 | JH2: 2024 | JI2: 2024 | JJ2: 2024 | JK2: 2024 | JL2: 2024 | JM2: 2024 | JN2: 2024 | JO2: 2025 | JP2: 2025 | JQ2: 2025 | JR2: 2025 | JS2: 2025 | JT2: 2025 | JU2: 2025 | JV2: 2025 | JW2: 2025 | JX2: 2025 | JY2: 2025 | JZ2: 2025 | KA2: 2026 | KB2: 2026 | KC2: 2026 | KD2: 2026 | KE2: 2026 | KF2: 2026 | KG2: 2026 | KH2: 2026 | KI2: 2026 | KJ2: 2026 | KK2: 2026 | KL2: 2026
A3: Customer name | B3: Parent Account | C3: Customer type | D3: Geo | E3: Vertical | G3: 44197 | H3: 44255 | I3: 44286 | J3: 44316 | K3: 44347 | L3: 44377 | M3: 44408 | N3: 44439 | O3: 44469 | P3: 44500 | Q3: 44530 | R3: 44561 | S3: 44592 | T3: 44620 | U3: 44651 | V3: 44681 | W3: 44712 | X3: 44742 | Y3: 44773 | Z3: 44804 | AA3: 44834 | AB3: 44865 | AC3: 44895 | AD3: 44926 | AE3: 44957 | AF3: 44985 | AG3: 45016 | AH3: 45046 | AI3: 45077 | AJ3: 45107 | AK3: 45138 | AL3: 45169 | AM3: 45199 | AN3: 45230 | AO3: 45260 | AP3: 45291 | AQ3: 45322 | AR3: 45351 | AS3: 45382 | AT3: 45412 | AU3: 45443 | AV3: 45473 | AW3: 45504 | AX3: 45535 | AY3: 45565 | AZ3: 45596 | BA3: 45626 | BB3: 45657 | BC3: 45688 | BD3: 45716 | BE3: 45747 | BF3: 45777 | BG3: 45808 | BH3: 45838 | BI3: 45869 | BJ3: 45900 | BK3: 45930 | BL3: 45961 | BM3: 45991 | BN3: 46022 | BO3: 46053 | BP3: 46081 | BQ3: 46112 | BR3: 46142 | BS3: 46173 | BT3: 46203 | BU3: 46234 | BV3: 46265 | BW3: 46295 | BX3: 46326 | BY3: 46356 | BZ3: 46387 | CC3: 44197 | CD3: 44255 | CE3: 44286 | CF3: 44316 | CG3: 44347 | CH3: 44377 | CI3: 44408 | CJ3: 44439 | CK3: 44469 | CL3: 44500 | CM3: 44530 | CN3: 44561 | CO3: 44592 | CP3: 44620 | CQ3: 44651 | CR3: 44681 | CS3: 44712 | CT3: 44742 | CU3: 44773 | CV3: 44804 | CW3: 44834 | CX3: 44865 | CY3: 44895 | CZ3: 44926 | DA3: 44957 | DB3: 44985 | DC3: 45016 | DD3: 45046 | DE3: 45077 | DF3: 45107 | DG3: 45138 | DH3: 45169 | DI3: 45199 | DJ3: 45230 | DK3: 45260 | DL3: 45291 | DM3: 45322 | DN3: 45351 | DO3: 45382 | DP3: 45412 | DQ3: 45443 | DR3: 45473 | DS3: 45504 | DT3: 45535 | DU3: 45565 | DV3: 45596 | DW3: 45626 | DX3: 45657 | DY3: 45688 | DZ3: 45716 | EA3: 45747 | EB3: 45777 | EC3: 45808 | ED3: 45838 | EE3: 45869 | EF3: 45900 | EG3: 45930 | EH3: 45961 | EI3: 45991 | EJ3: 46022 | EK3: 46053 | EL3: 46081 | EM3: 46112 | EN3: 46142 | EO3: 46173 | EP3: 46203 | EQ3: 46234 | ER3: 46265 | ES3: 46295 | ET3: 46326 | EU3: 46356 | EV3: 46387 | EX3: 44197 | EY3: 44255 | EZ3: 44286 | FA3: 44316 | FB3: 44347 | FC3: 44377 | FD3: 44408 | FE3: 44439 | FF3: 44469 | FG3: 44500 | FH3: 44530 | FI3: 44561 | FJ3: 44592 | FK3: 44620 | FL3: 44651 | FM3: 44681 | FN3: 44712 | FO3: 44742 | FP3: 44773 | FQ3: 44804 | FR3: 44834 | FS3: 44865 | FT3: 44895 | FU3: 44926 | FV3: 44957 | FW3: 44985 | FX3: 45016 | FY3: 45046 | FZ3: 45077 | GA3: 45107 | GB3: 45138 | GC3: 45169 | GD3: 45199 | GE3: 45230 | GF3: 45260 | GG3: 45291 | GH3: 45322 | GI3: 45351 | GJ3: 45382 | GK3: 45412 | GL3: 45443 | GM3: 45473 | GN3: 45504 | GO3: 45535 | GP3: 45565 | GQ3: 45596 | GR3: 45626 | GS3: 45657 | GT3: 45688 | GU3: 45716 | GV3: 45747 | GW3: 45777 | GX3: 45808 | GY3: 45838 | GZ3: 45869 | HA3: 45900 | HB3: 45930 | HC3: 45961 | HD3: 45991 | HE3: 46022 | HF3: 46053 | HG3: 46081 | HH3: 46112 | HI3: 46142 | HJ3: 46173 | HK3: 46203 | HL3: 46234 | HM3: 46265 | HN3: 46295 | HO3: 46326 | HP3: 46356 | HQ3: 46387 | HS3: 44197 | HT3: 44255 | HU3: 44286 | HV3: 44316 | HW3: 44347 | HX3: 44377 | HY3: 44408 | HZ3: 44439 | IA3: 44469 | IB3: 44500 | IC3: 44530 | ID3: 44561 | IE3: 44592 | IF3: 44620 | IG3: 44651 | IH3: 44681 | II3: 44712 | IJ3: 44742 | IK3: 44773 | IL3: 44804 | IM3: 44834 | IN3: 44865 | IO3: 44895 | IP3: 44926 | IQ3: 44957 | IR3: 44985 | IS3: 45016 | IT3: 45046 | IU3: 45077 | IV3: 45107 | IW3: 45138 | IX3: 45169 | IY3: 45199 | IZ3: 45230 | JA3: 45260 | JB3: 45291 | JC3: 45322 | JD3: 45351 | JE3: 45382 | JF3: 45412 | JG3: 45443 | JH3: 45473 | JI3: 45504 | JJ3: 45535 | JK3: 45565 | JL3: 45596 | JM3: 45626 | JN3: 45657 | JO3: 45688 | JP3: 45716 | JQ3: 45747 | JR3: 45777 | JS3: 45808 | JT3: 45838 | JU3: 45869 | JV3: 45900 | JW3: 45930 | JX3: 45961 | JY3: 45991 | JZ3: 46022 | KA3: 46053 | KB3: 46081 | KC3: 46112 | KD3: 46142 | KE3: 46173 | KF3: 46203 | KG3: 46234 | KH3: 46265 | KI3: 46295 | KJ3: 46326 | KK3: 46356 | KL3: 46387
A5: Summary
